Workbook
Name Net_Sales: 'Sales Data '!$F$4:$F$1082
Name Region: 'Sales Data '!$D$4:$D$1082
Name Salesman: 'Sales Data '!$C$4:$C$1082

Sheet Students Grade
A1: Student ID | B1: Name | C1: Math | D1: Science | E1: English | F1: Enrollment Date | G1: Total in % | H1: Grade | I1: Above 80?
A2: 1001 | B2: Student 1 | C2: 61 | D2: 48 | E2: 76 | F2: 43101 | G2: {=SUM(C2:E2/300*100)/100} -> 0.61666667 | H2: =IF(G2>=80%,"A",IF(G2>=60%,"B",IF(G2>=40%,"C","Fail"))) -> B | I2: =IF(AND(C2>80,D2>80),"Yes","No") -> No | K2: Cretiria | L2: Grade
A3: 1002 | B3: Student 2 | C3: 78 | D3: 76 | E3: 70 | F3: 43281 | G3: {=SUM(C3:E3/300*100)/100} -> 0.74666667 | H3: =IF(G3>=80%,"A",IF(G3>=60%,"B",IF(G3>=40%,"C","Fail"))) -> B | I3: =IF(AND(C3>80,D3>80),"Yes","No") -> No | K3: ≥ 80 | L3: A | R3: CountIF- Student Scored above 50 in maths | Y3: Extract the first name from full names using LEFT and FIND. | Z3: Convert names to uppercase/lowercase using UPPER(), LOWER().
A4: 1003 | B4: Student 3 | C4: 97 | D4: 60 | E4: 51 | F4: 43461 | G4: {=SUM(C4:E4/300*100)/100} -> 0.69333333 | H4: =IF(G4>=80%,"A",IF(G4>=60%,"B",IF(G4>=40%,"C","Fail"))) -> B | I4: =IF(AND(C4>80,D4>80),"Yes","No") -> No | K4: 60 – 79 | L4: B | R4: =COUNTIF(C2:C21,">50") -> 19 | X4: Student ID | Y4: Name | Z4: Name
A5: 1004 | B5: Student 4 | C5: 74 | D5: 55 | E5: 46 | F5: 43641 | G5: {=SUM(C5:E5/300*100)/100} -> 0.58333333 | H5: =IF(G5>=80%,"A",IF(G5>=60%,"B",IF(G5>=40%,"C","Fail"))) -> C | I5: =IF(AND(C5>80,D5>80),"Yes","No") -> No | K5: 40 – 59 | L5: C | X5: 1001 | Y5: =LEFT('Students Grade'!B2,FIND(" ",'Students Grade'!B2)-1) -> Student | Z5: =UPPER('Students Grade'!B2) -> STUDENT 1
A6: 1005 | B6: Student 5 | C6: 68 | D6: 74 | E6: 84 | F6: 43821 | G6: {=SUM(C6:E6/300*100)/100} -> 0.75333333 | H6: =IF(G6>=80%,"A",IF(G6>=60%,"B",IF(G6>=40%,"C","Fail"))) -> B | I6: =IF(AND(C6>80,D6>80),"Yes","No") -> No | K6: < 40 | L6: Fail | R6: AverageIF- Student Scored above 60 | X6: 1002 | Y6: =LEFT('Students Grade'!B3,FIND(" ",'Students Grade'!B3)-1) -> Student | Z6: =UPPER('Students Grade'!B3) -> STUDENT 2
A7: 1006 | B7: Student 6 | C7: 80 | D7: 70 | E7: 65 | F7: 44001 | G7: {=SUM(C7:E7/300*100)/100} -> 0.71666667 | H7: =IF(G7>=80%,"A",IF(G7>=60%,"B",IF(G7>=40%,"C","Fail"))) -> B | I7: =IF(AND(C7>80,D7>80),"Yes","No") -> No | R7: {=AVERAGE(IF((C2:C21>60)*(D2:D21>60)*(E2:E21>60),(C2:C21+D2:D21+E2:E21)/3))/100} -> 0.79333333 | X7: 1003 | Y7: =LEFT('Students Grade'!B4,FIND(" ",'Students Grade'!B4)-1) -> Student | Z7: =UPPER('Students Grade'!B4) -> STUDENT 3
A8: 1007 | B8: Student 7 | C8: 75 | D8: 47 | E8: 78 | F8: 44181 | G8: {=SUM(C8:E8/300*100)/100} -> 0.66666667 | H8: =IF(G8>=80%,"A",IF(G8>=60%,"B",IF(G8>=40%,"C","Fail"))) -> B | I8: =IF(AND(C8>80,D8>80),"Yes","No") -> No | X8: 1004 | Y8: =LEFT('Students Grade'!B5,FIND(" ",'Students Grade'!B5)-1) -> Student | Z8: =UPPER('Students Grade'!B5) -> STUDENT 4
A9: 1008 | B9: Student 8 | C9: 94 | D9: 67 | E9: 64 | F9: 44361 | G9: {=SUM(C9:E9/300*100)/100} -> 0.75 | H9: =IF(G9>=80%,"A",IF(G9>=60%,"B",IF(G9>=40%,"C","Fail"))) -> B | I9: =IF(AND(C9>80,D9>80),"Yes","No") -> No | X9: 1005 | Y9: =LEFT('Students Grade'!B6,FIND(" ",'Students Grade'!B6)-1) -> Student | Z9: =UPPER('Students Grade'!B6) -> STUDENT 5
A10: 1009 | B10: Student 9 | C10: 41 | D10: 75 | E10: 56 | F10: 44541 | G10: {=SUM(C10:E10/300*100)/100} -> 0.57333333 | H10: =IF(G10>=80%,"A",IF(G10>=60%,"B",IF(G10>=40%,"C","Fail"))) -> C | I10: =IF(AND(C10>80,D10>80),"Yes","No") -> No | X10: 1006 | Y10: =LEFT('Students Grade'!B7,FIND(" ",'Students Grade'!B7)-1) -> Student | Z10: =UPPER('Students Grade'!B7) -> STUDENT 6
A11: 1010 | B11: Student 10 | C11: 98 | D11: 54 | E11: 58 | F11: 44721 | G11: {=SUM(C11:E11/300*100)/100} -> 0.7 | H11: =IF(G11>=80%,"A",IF(G11>=60%,"B",IF(G11>=40%,"C","Fail"))) -> B | I11: =IF(AND(C11>80,D11>80),"Yes","No") -> No | X11: 1007 | Y11: =LEFT('Students Grade'!B8,FIND(" ",'Students Grade'!B8)-1) -> Student | Z11: =UPPER('Students Grade'!B8) -> STUDENT 7
A12: 1011 | B12: Student 11 | C12: 73 | D12: 79 | E12: 53 | F12: 44901 | G12: {=SUM(C12:E12/300*100)/100} -> 0.68333333 | H12: =IF(G12>=80%,"A",IF(G12>=60%,"B",IF(G12>=40%,"C","Fail"))) -> B | I12: =IF(AND(C12>80,D12>80),"Yes","No") -> No | X12: 1008 | Y12: =LEFT('Students Grade'!B9,FIND(" ",'Students Grade'!B9)-1) -> Student | Z12: =UPPER('Students Grade'!B9) -> STUDENT 8
A13: 1012 | B13: Student 12 | C13: 85 | D13: 89 | E13: 79 | F13: 45081 | G13: {=SUM(C13:E13/300*100)/100} -> 0.84333333 | H13: =IF(G13>=80%,"A",IF(G13>=60%,"B",IF(G13>=40%,"C","Fail"))) -> A | I13: =IF(AND(C13>80,D13>80),"Yes","No") -> Yes | X13: 1009 | Y13: =LEFT('Students Grade'!B10,FIND(" ",'Students Grade'!B10)-1) -> Student | Z13: =UPPER('Students Grade'!B10) -> STUDENT 9
A14: 1013 | B14: Student 13 | C14: 98 | D14: 90 | E14: 97 | F14: 45261 | G14: {=SUM(C14:E14/300*100)/100} -> 0.95 | H14: =IF(G14>=80%,"A",IF(G14>=60%,"B",IF(G14>=40%,"C","Fail"))) -> A | I14: =IF(AND(C14>80,D14>80),"Yes","No") -> Yes | R14: Find the difference in days between two dates in days | X14: 1010 | Y14: =LEFT('Students Grade'!B11,FIND(" ",'Students Grade'!B11)-1) -> Student | Z14: =UPPER('Students Grade'!B11) -> STUDENT 10
A15: 1014 | B15: Student 14 | C15: 93 | D15: 40 | E15: 44 | F15: 45441 | G15: {=SUM(C15:E15/300*100)/100} -> 0.59 | H15: =IF(G15>=80%,"A",IF(G15>=60%,"B",IF(G15>=40%,"C","Fail"))) -> C | I15: =IF(AND(C15>80,D15>80),"Yes","No") -> No | R15: =DATEDIF('Students Grade'!F2,'Students Grade'!F3,"D") -> 180 | X15: 1011 | Y15: =LEFT('Students Grade'!B12,FIND(" ",'Students Grade'!B12)-1) -> Student | Z15: =LOWER('Students Grade'!B12) -> student 11
A16: 1015 | B16: Student 15 | C16: 70 | D16: 51 | E16: 75 | F16: 45621 | G16: {=SUM(C16:E16/300*100)/100} -> 0.65333333 | H16: =IF(G16>=80%,"A",IF(G16>=60%,"B",IF(G16>=40%,"C","Fail"))) -> B | I16: =IF(AND(C16>80,D16>80),"Yes","No") -> No | X16: 1012 | Y16: =LEFT('Students Grade'!B13,FIND(" ",'Students Grade'!B13)-1) -> Student | Z16: =LOWER('Students Grade'!B13) -> student 12
A17: 1016 | B17: Student 16 | C17: 98 | D17: 77 | E17: 60 | F17: 45801 | G17: {=SUM(C17:E17/300*100)/100} -> 0.78333333 | H17: =IF(G17>=80%,"A",IF(G17>=60%,"B",IF(G17>=40%,"C","Fail"))) -> B | I17: =IF(AND(C17>80,D17>80),"Yes","No") -> No | X17: 1013 | Y17: =LEFT('Students Grade'!B14,FIND(" ",'Students Grade'!B14)-1) -> Student | Z17: =LOWER('Students Grade'!B14) -> student 13
A18: 1017 | B18: Student 17 | C18: 66 | D18: 59 | E18: 40 | F18: 45981 | G18: {=SUM(C18:E18/300*100)/100} -> 0.55 | H18: =IF(G18>=80%,"A",IF(G18>=60%,"B",IF(G18>=40%,"C","Fail"))) -> C | I18: =IF(AND(C18>80,D18>80),"Yes","No") -> No | X18: 1014 | Y18: =LEFT('Students Grade'!B15,FIND(" ",'Students Grade'!B15)-1) -> Student | Z18: =LOWER('Students Grade'!B15) -> student 14
A19: 1018 | B19: Student 18 | C19: 82 | D19: 48 | E19: 79 | F19: 46161 | G19: {=SUM(C19:E19/300*100)/100} -> 0.69666667 | H19: =IF(G19>=80%,"A",IF(G19>=60%,"B",IF(G19>=40%,"C","Fail"))) -> B | I19: =IF(AND(C19>80,D19>80),"Yes","No") -> No | X19: 1015 | Y19: =LEFT('Students Grade'!B16,FIND(" ",'Students Grade'!B16)-1) -> Student | Z19: =LOWER('Students Grade'!B16) -> student 15
A20: 1019 | B20: Student 19 | C20: 90 | D20: 78 | E20: 60 | F20: 46341 | G20: {=SUM(C20:E20/300*100)/100} -> 0.76 | H20: =IF(G20>=80%,"A",IF(G20>=60%,"B",IF(G20>=40%,"C","Fail"))) -> B | I20: =IF(AND(C20>80,D20>80),"Yes","No") -> No | X20: 1016 | Y20: =LEFT('Students Grade'!B17,FIND(" ",'Students Grade'!B17)-1) -> Student | Z20: =LOWER('Students Grade'!B17) -> student 16
A21: 1020 | B21: Student 20 | C21: 83 | D21: 92 | E21: 55 | F21: 46521 | G21: {=SUM(C21:E21/300*100)/100} -> 0.76666667 | H21: =IF(G21>=80%,"A",IF(G21>=60%,"B",IF(G21>=40%,"C","Fail"))) -> B | I21: =IF(AND(C21>80,D21>80),"Yes","No") -> Yes | X21: 1017 | Y21: =LEFT('Students Grade'!B18,FIND(" ",'Students Grade'!B18)-1) -> Student | Z21: =LOWER('Students Grade'!B18) -> student 17
A22: 1021 | B22: Student 21 | C22: 32 | D22: 21 | E22: 54 | F22: 46522 | G22: {=SUM(C22:E22/300*100)/100} -> 0.35666667 | H22: =IF(G22>=80%,"A",IF(G22>=60%,"B",IF(G22>=40%,"C","Fail"))) -> Fail | I22: =IF(AND(C22>80,D22>80),"Yes","No") -> No | X22: 1018 | Y22: =LEFT('Students Grade'!B19,FIND(" ",'Students Grade'!B19)-1) -> Student | Z22: =LOWER('Students Grade'!B19) -> student 18
X23: 1019 | Y23: =LEFT('Students Grade'!B20,FIND(" ",'Students Grade'!B20)-1) -> Student | Z23: =LOWER('Students Grade'!B20) -> student 19
X24: 1020 | Y24: =LEFT('Students Grade'!B21,FIND(" ",'Students Grade'!B21)-1) -> Student | Z24: =LOWER('Students Grade'!B21) -> student 20
K25: Vlookup
K26: Student ID | L26: Name
K27: 1001 | L27: =VLOOKUP(K27,'Students Grade'!A1:B21,2,TRUE) -> Student 1
K28: 1002 | L28: =VLOOKUP(K28,'Students Grade'!A2:B22,2,TRUE) -> Student 2
K29: 1003 | L29: =VLOOKUP(K29,'Students Grade'!A3:B23,2,TRUE) -> Student 3 | P29: Filter
K30: 1004 | L30: =VLOOKUP(K30,'Students Grade'!A4:B24,2,TRUE) -> Student 4 | P30: Extract a list of top-performing students based on scores.
K31: 1005 | L31: =VLOOKUP(K31,'Students Grade'!A5:B25,2,TRUE) -> Student 5 | P31: Name | Q31: Math | R31: Science | S31: English
K32: 1006 | L32: =VLOOKUP(K32,'Students Grade'!A6:B26,2,TRUE) -> Student 6 | P32: {=_xlfn._xlws.FILTER('Students Grade'!B2:E21,(('Students Grade'!C2:C21+'Students Grade'!D2:D21+'Students Grade'!E2:E21)/3)>=80,"No students found")} -> Student 12 | Q32: 85 | R32: 89 | S32: 79
K33: 1007 | L33: =VLOOKUP(K33,'Students Grade'!A7:B27,2,TRUE) -> Student 7 | P33: Student 13 | Q33: 98 | R33: 90 | S33: 97
K34: 1008 | L34: =VLOOKUP(K34,'Students Grade'!A8:B28,2,TRUE) -> Student 8
K35: 1009 | L35: =VLOOKUP(K35,'Students Grade'!A9:B29,2,TRUE) -> Student 9
K36: 1010 | L36: =VLOOKUP(K36,'Students Grade'!A10:B30,2,TRUE) -> Student 10
K37: 1011 | L37: =VLOOKUP(K37,'Students Grade'!A11:B31,2,TRUE) -> Student 11
K38: 1012 | L38: =VLOOKUP(K38,'Students Grade'!A12:B32,2,TRUE) -> Student 12 | Q38: Indirect Function
K39: 1013 | L39: =VLOOKUP(K39,'Students Grade'!A13:B33,2,TRUE) -> Student 13 | P39: {=INDEX(A1:A11,0,0)} -> Student ID | Q39: {=INDEX(B1:E11,0,0)} -> Name | R39: Math | S39: Science | T39: English
K40: 1014 | L40: =VLOOKUP(K40,'Students Grade'!A14:B34,2,TRUE) -> Student 14 | P40: 1001 | Q40: Student 1 | R40: 61 | S40: 48 | T40: 76
...

Sheet Sales Data 
A1: Sales ID | B1: Product | C1: Region | D1: Salesperson | E1: Amount | F1: Date | G1: Discount | H1: Discount
A2: 2001 | B2: Keyboard | C2: South | D2: Person 1 | E2: 7048 | F2: 44927 | G2: =IF(E2>30000,15%,IF(E2>=20000,10%,5%)) -> 0.05 | H2: =IF(OR(E2>15000),"Eligible","Not Eligible") -> Not Eligible | R2: Vlookup
A3: 2002 | B3: Printer | C3: West | D3: Person 2 | E3: 17428 | F3: 44942 | G3: =IF(E3>30000,15%,IF(E3>=20000,10%,5%)) -> 0.05 | H3: =IF(OR(E3>15000),"Eligible","Not Eligible") -> Eligible | J3: Price Threshold | M3: SUMIFS Formula Example 1 | Q3: Sales ID | R3: Product | S3: Amount | X3: Xlookup
A4: 2003 | B4: Mouse | C4: South | D4: Person 3 | E4: 23672 | F4: 44957 | G4: =IF(E4>30000,15%,IF(E4>=20000,10%,5%)) -> 0.1 | H4: =IF(OR(E4>15000),"Eligible","Not Eligible") -> Eligible | J4: Amount | K4: Discount | N4: Conditions | Q4: 2001 | R4: Keyboard | S4: =VLOOKUP(R4,B2:E21,4,FALSE) -> 7048 | X4: Search for salesperson performance based on flexible search criteria.
A5: 2004 | B5: Printer | C5: East | D5: Person 4 | E5: 5264 | F5: 44972 | G5: =IF(E5>30000,15%,IF(E5>=20000,10%,5%)) -> 0.05 | H5: =IF(OR(E5>15000),"Eligible","Not Eligible") -> Not Eligible | J5: >30000 | K5: 0.15 | N5: Keyboard | Q5: 2002 | R5: Printer | S5: =VLOOKUP(R5,B3:E22,4,FALSE) -> 17428 | W5: Region | X5: Salesperson
A6: 2005 | B6: Keyboard | C6: North | D6: Person 5 | E6: 43388 | F6: 44987 | G6: =IF(E6>30000,15%,IF(E6>=20000,10%,5%)) -> 0.15 | H6: =IF(OR(E6>15000),"Eligible","Not Eligible") -> Eligible | J6: 20k-30k | K6: 0.1 | N6: South | Q6: 2003 | R6: Mouse | S6: =VLOOKUP(R6,B4:E23,4,FALSE) -> 23672 | W6: South | X6: =_xlfn.XLOOKUP(W6,C2:C21,D2:D21,,0) -> Person 1
A7: 2006 | B7: Mouse | C7: North | D7: Person 6 | E7: 19757 | F7: 45002 | G7: =IF(E7>30000,15%,IF(E7>=20000,10%,5%)) -> 0.05 | H7: =IF(OR(E7>15000),"Eligible","Not Eligible") -> Eligible | J7: <20,000 | K7: 0.05 | Q7: 2004 | R7: Printer | S7: =VLOOKUP(R7,B5:E24,4,FALSE) -> 5264 | W7: East | X7: =_xlfn.XLOOKUP(W7,C3:C22,D3:D22,,0) -> Person 4
A8: 2007 | B8: Mouse | C8: East | D8: Person 7 | E8: 32058 | F8: 45017 | G8: =IF(E8>30000,15%,IF(E8>=20000,10%,5%)) -> 0.15 | H8: =IF(OR(E8>15000),"Eligible","Not Eligible") -> Eligible | J8: otherwise | K8: no | M8: Result | Q8: 2005 | R8: Keyboard | S8: =VLOOKUP(R8,B6:E25,4,FALSE) -> 43388 | W8: North | X8: =_xlfn.XLOOKUP(W8,C4:C23,D4:D23,,0) -> Person 5
A9: 2008 | B9: Keyboard | C9: East | D9: Person 8 | E9: 46429 | F9: 45032 | G9: =IF(E9>30000,15%,IF(E9>=20000,10%,5%)) -> 0.15 | H9: =IF(OR(E9>15000),"Eligible","Not Eligible") -> Eligible | M9: =SUMIFS(E2:E21,B2:B21,"Keyboard",C2:C21,"South") -> 42233 | Q9: 2006 | R9: Mouse | S9: =VLOOKUP(R9,B7:E26,4,FALSE) -> 19757 | W9: West | X9: =_xlfn.XLOOKUP(W9,C5:C24,D5:D24,,0) -> Person 18
A10: 2009 | B10: Printer | C10: East | D10: Person 9 | E10: 19746 | F10: 45047 | G10: =IF(E10>30000,15%,IF(E10>=20000,10%,5%)) -> 0.05 | H10: =IF(OR(E10>15000),"Eligible","Not Eligible") -> Eligible | Q10: 2007 | R10: Mouse | S10: =VLOOKUP(R10,B8:E27,4,FALSE) -> 32058
A11: 2010 | B11: Keyboard | C11: South | D11: Person 10 | E11: 35185 | F11: 45062 | G11: =IF(E11>30000,15%,IF(E11>=20000,10%,5%)) -> 0.15 | H11: =IF(OR(E11>15000),"Eligible","Not Eligible") -> Eligible | J11: Elegibility Criteria | Q11: 2008 | R11: Keyboard | S11: =VLOOKUP(R11,B9:E28,4,FALSE) -> 46429
A12: 2011 | B12: Keyboard | C12: East | D12: Person 11 | E12: 33920 | F12: 45077 | G12: =IF(E12>30000,15%,IF(E12>=20000,10%,5%)) -> 0.15 | H12: =IF(OR(E12>15000),"Eligible","Not Eligible") -> Eligible | J12: >15,000 | K12: Not Elegibile | Q12: 2009 | R12: Printer | S12: =VLOOKUP(R12,B10:E29,4,FALSE) -> 19746
A13: 2012 | B13: Monitor | C13: North | D13: Person 12 | E13: 35611 | F13: 45092 | G13: =IF(E13>30000,15%,IF(E13>=20000,10%,5%)) -> 0.15 | H13: =IF(OR(E13>15000),"Eligible","Not Eligible") -> Eligible | Q13: 2010 | R13: Keyboard | S13: =VLOOKUP(R13,B11:E30,4,FALSE) -> 35185
A14: 2013 | B14: Laptop | C14: East | D14: Person 13 | E14: 15560 | F14: 45107 | G14: =IF(E14>30000,15%,IF(E14>=20000,10%,5%)) -> 0.05 | H14: =IF(OR(E14>15000),"Eligible","Not Eligible") -> Eligible | Q14: 2011 | R14: Keyboard | S14: =VLOOKUP(R14,B12:E31,4,FALSE) -> 33920
A15: 2014 | B15: Laptop | C15: South | D15: Person 14 | E15: 7283 | F15: 45122 | G15: =IF(E15>30000,15%,IF(E15>=20000,10%,5%)) -> 0.05 | H15: =IF(OR(E15>15000),"Eligible","Not Eligible") -> Not Eligible | L15: index and match | Q15: 2012 | R15: Monitor | S15: =VLOOKUP(R15,B13:E32,4,FALSE) -> 35611
A16: 2015 | B16: Laptop | C16: East | D16: Person 15 | E16: 15678 | F16: 45137 | G16: =IF(E16>30000,15%,IF(E16>=20000,10%,5%)) -> 0.05 | H16: =IF(OR(E16>15000),"Eligible","Not Eligible") -> Eligible | J16: Find sales values for a specific salesperson in a specific month. | Q16: 2013 | R16: Laptop | S16: =VLOOKUP(R16,B14:E33,4,FALSE) -> 15560
A17: 2016 | B17: Mouse | C17: East | D17: Person 16 | E17: 5277 | F17: 45152 | G17: =IF(E17>30000,15%,IF(E17>=20000,10%,5%)) -> 0.05 | H17: =IF(OR(E17>15000),"Eligible","Not Eligible") -> Not Eligible | K17: Date | L17: Amount | Q17: 2014 | R17: Laptop | S17: =VLOOKUP(R17,B15:E34,4,FALSE) -> 7283
A18: 2017 | B18: Monitor | C18: North | D18: Person 17 | E18: 41871 | F18: 45167 | G18: =IF(E18>30000,15%,IF(E18>=20000,10%,5%)) -> 0.15 | H18: =IF(OR(E18>15000),"Eligible","Not Eligible") -> Eligible | K18: 44942 | L18: {=INDEX(E2:E21,MATCH(K18,F2:F21,0))} -> 17428 | Q18: 2015 | R18: Laptop | S18: =VLOOKUP(R18,B16:E35,4,FALSE) -> 15678
A19: 2018 | B19: Monitor | C19: West | D19: Person 18 | E19: 38161 | F19: 45182 | G19: =IF(E19>30000,15%,IF(E19>=20000,10%,5%)) -> 0.15 | H19: =IF(OR(E19>15000),"Eligible","Not Eligible") -> Eligible | Q19: 2016 | R19: Mouse | S19: =VLOOKUP(R19,B17:E36,4,FALSE) -> 5277
A20: 2019 | B20: Mouse | C20: West | D20: Person 19 | E20: 30436 | F20: 45197 | G20: =IF(E20>30000,15%,IF(E20>=20000,10%,5%)) -> 0.15 | H20: =IF(OR(E20>15000),"Eligible","Not Eligible") -> Eligible | Q20: 2017 | R20: Monitor | S20: =VLOOKUP(R20,B18:E37,4,FALSE) -> 41871
A21: 2020 | B21: Printer | C21: West | D21: Person 20 | E21: 33953 | F21: 45212 | G21: =IF(E21>30000,15%,IF(E21>=20000,10%,5%)) -> 0.15 | H21: =IF(OR(E21>15000),"Eligible","Not Eligible") -> Eligible | Q21: 2018 | R21: Monitor | S21: =VLOOKUP(R21,B19:E38,4,FALSE) -> 38161
Q22: 2019 | R22: Mouse | S22: =VLOOKUP(R22,B20:E39,4,FALSE) -> 30436
Q23: 2020 | R23: Printer | S23: =VLOOKUP(R23,B21:E40,4,FALSE) -> 33953
L24: Xmatch
L25: Keyboard | M25: =_xlfn.XMATCH(L25,B2:B21,0) -> 1
L26: Printer | M26: =_xlfn.XMATCH(L26,B2:B21,0) -> 2
L27: Mouse | M27: =_xlfn.XMATCH(L27,B2:B21,0) -> 3
D28: Offset | L28: Printer | M28: =_xlfn.XMATCH(L28,B2:B21,0) -> 2
C29: Create dynamic ranges for sales trends. | L29: Keyboard | M29: =_xlfn.XMATCH(L29,B2:B21,0) -> 1
C30: Product | D30: Region | E30: Salesperson | F30: Amount | L30: Mouse | M30: =_xlfn.XMATCH(L30,B2:B21,0) -> 3
C31: {=OFFSET(A2,2,1,6,4)} -> Mouse | D31: South | E31: Person 3 | F31: 23672 | L31: Mouse | M31: =_xlfn.XMATCH(L31,B2:B21,0) -> 3
C32: Printer | D32: East | E32: Person 4 | F32: 5264 | L32: Keyboard | M32: =_xlfn.XMATCH(L32,B2:B21,0) -> 1
C33: Keyboard | D33: North | E33: Person 5 | F33: 43388
C34: Mouse | D34: North | E34: Person 6 | F34: 19757
C35: Mouse | D35: East | E35: Person 7 | F35: 32058
C36: Keyboard | D36: East | E36: Person 8 | F36: 46429

Sheet Employee Data
A1: Employee ID | B1: Name | C1: Department | D1: Salary | E1: Joining Date
A2: 3001 | B2: Employee 1 | C2: Finance | D2: 86766 | E2: 42005 | L2: Math Function
A3: 3002 | B3: Employee 2 | C3: Finance | D3: 31943 | E3: 42255 | L3: Round | M3: Ceiling | N3: Floor | X3: Xlookup
A4: 3003 | B4: Employee 3 | C4: HR | D4: 63374 | E4: 42505 | L4: {=ROUND('Employee Data'!D2:D21,2)} -> 86766 | M4: {=CEILING('Employee Data'!D2:D21,500)} -> 87000 | N4: {=FLOOR('Employee Data'!D2:D21,500)} -> 86500 | R4: Difference Between Joining date of two employee | X4: Find employee salaries without worrying about sorted data.
A5: 3004 | B5: Employee 4 | C5: Finance | D5: 109972 | E5: 42755 | L5: 31943 | M5: 32000 | N5: 31500 | Q5: Days | R5: =DATEDIF(E2,E3,"D") -> 250 | W5: Name | X5: Salary
A6: 3005 | B6: Employee 5 | C6: IT | D6: 54149 | E6: 43005 | L6: 63374 | M6: 63500 | N6: 63000 | W6: Employee 2 | X6: =_xlfn.XLOOKUP(W6,B2:B21,D2:D21,,0) -> 31943
A7: 3006 | B7: Employee 6 | C7: IT | D7: 78689 | E7: 43255 | L7: 109972 | M7: 110000 | N7: 109500
A8: 3007 | B8: Employee 7 | C8: Marketing | D8: 35960 | E8: 43505 | L8: 54149 | M8: 54500 | N8: 54000
A9: 3008 | B9: Employee 8 | C9: IT | D9: 91659 | E9: 43755 | L9: 78689 | M9: 79000 | N9: 78500
A10: 3009 | B10: Employee 9 | C10: IT | D10: 90423 | E10: 44005 | L10: 35960 | M10: 36000 | N10: 35500
A11: 3010 | B11: Employee 10 | C11: HR | D11: 107877 | E11: 44255 | L11: 91659 | M11: 92000 | N11: 91500 | V11: Index and Match
A12: 3011 | B12: Employee 11 | C12: Finance | D12: 107634 | E12: 44505 | L12: 90423 | M12: 90500 | N12: 90000 | W12: Look up employee details dynamically without column restrictions.
A13: 3012 | B13: Employee 12 | C13: Finance | D13: 35226 | E13: 44755 | L13: 107877 | M13: 108000 | N13: 107500 | W13: Name | X13: Employee 2
A14: 3013 | B14: Employee 13 | C14: HR | D14: 40872 | E14: 45005 | L14: 107634 | M14: 108000 | N14: 107500 | W14: Department | X14: Finance
A15: 3014 | B15: Employee 14 | C15: HR | D15: 55378 | E15: 45255 | L15: 35226 | M15: 35500 | N15: 35000 | W15: Salary | X15: {=INDEX(D2:D21,MATCH(X13,B2:B21,0),MATCH(X14,C2:C21,0))} -> 31943
A16: 3015 | B16: Employee 15 | C16: HR | D16: 63297 | E16: 45505 | L16: 40872 | M16: 41000 | N16: 40500
A17: 3016 | B17: Employee 16 | C17: Finance | D17: 114173 | E17: 45755 | L17: 55378 | M17: 55500 | N17: 55000
A18: 3017 | B18: Employee 17 | C18: HR | D18: 86915 | E18: 46005 | L18: 63297 | M18: 63500 | N18: 63000
A19: 3018 | B19: Employee 18 | C19: IT | D19: 116284 | E19: 46255 | L19: 114173 | M19: 114500 | N19: 114000
A20: 3019 | B20: Employee 19 | C20: Marketing | D20: 116283 | E20: 46505 | L20: 86915 | M20: 87000 | N20: 86500
A21: 3020 | B21: Employee 20 | C21: Marketing | D21: 99924 | E21: 46755 | L21: 116284 | M21: 116500 | N21: 116000
L22: 116283 | M22: 116500 | N22: 116000
L23: 99924 | M23: 100000 | N23: 99500
